{"date":"Fri Jul 05 2024 11:29:39 GMT-0700 (Pacific Daylight Time)","error":{"code":"ERR_UNHANDLED_REJECTION"},"exception":true,"level":"error","message":"uncaughtException: This error originated either by throwing inside of an async function without a catch block, or by rejecting a promise which was not handled with .catch(). The promise rejected with the reason \"something bad happened\".\nUnhandledPromiseRejection: This error originated either by throwing inside of an async function without a catch block, or by rejecting a promise which was not handled with .catch(). The promise rejected with the reason \"something bad happened\".","os":{"loadavg":[1.92529296875,2.01171875,2.564453125],"uptime":86863},"process":{"argv":["/Users/bray/.nvm/versions/node/v20.6.1/bin/node","/Users/bray/Desktop/WebProjects/BP/app.js"],"cwd":"/Users/bray/Desktop/WebProjects/BP","execPath":"/Users/bray/.nvm/versions/node/v20.6.1/bin/node","gid":20,"memoryUsage":{"arrayBuffers":17363,"external":2397545,"heapTotal":84045824,"heapUsed":65126152,"rss":122249216},"pid":6304,"uid":501,"version":"v20.6.1"},"stack":"UnhandledPromiseRejection: This error originated either by throwing inside of an async function without a catch block, or by rejecting a promise which was not handled with .catch(). The promise rejected with the reason \"something bad happened\".","trace":[]}